[2025-07-04 16:17:17,900] INFO: üéØ MASTER PIPELINE ORCHESTRATOR STARTING
[2025-07-04 16:17:17,900] INFO: ============================================================
[2025-07-04 16:17:17,901] INFO: Timestamp: 2025-07-04T16:17:17.901234
[2025-07-04 16:17:17,901] INFO: Arguments: {'full': True, 'universe': False, 'portfolio': False, 'historical_gspread': False, 'gspread_analytics': False, 'runs': False, 'dry_run': False, 'validate_only': False, 'resume_from': None, 'force': False, 'parallel': True, 'config': 'config/config.yaml', 'log_level': 'INFO', 'log_file': None, 'monitor': False, 'report': True, 'notify': None}
[2025-07-04 16:17:17,901] INFO: ============================================================
[2025-07-04 16:17:17,910] INFO: üìã Creating pipeline execution plan...
[2025-07-04 16:17:17,910] INFO: üìä Execution plan created:
[2025-07-04 16:17:17,910] INFO:   Stages: 6
[2025-07-04 16:17:17,910] INFO:   Parallel groups: 2
[2025-07-04 16:17:17,910] INFO:   Estimated duration: 0:07:00
[2025-07-04 16:17:17,915] INFO: üöÄ Starting pipeline execution...
[2025-07-04 16:17:17,916] INFO: üìç Executing step 1/2: ['portfolio', 'runs-excel', 'universe', 'historical-gspread']
[2025-07-04 16:17:17,916] INFO: üîÑ Executing portfolio...
[2025-07-04 16:17:17,927] INFO: üîÑ Executing runs-excel...
[2025-07-04 16:17:17,936] INFO: üîÑ Executing universe...
[2025-07-04 16:17:17,950] INFO: üîÑ Executing historical-gspread...
[2025-07-04 16:17:20,953] ERROR: ‚ùå runs-excel failed after 0:00:03.024701
[2025-07-04 16:17:22,078] INFO: ‚úÖ portfolio completed in 0:00:04.161705
[2025-07-04 16:17:22,078] INFO:    Records processed: 21,662
[2025-07-04 16:17:22,079] INFO:    Output files: 1
[2025-07-04 16:17:22,211] ERROR: ‚ùå historical-gspread failed after 0:00:04.260441
[2025-07-04 16:17:22,211] ERROR:    Error: --- Logging error ---
Traceback (most recent call last):
  File "C:\Users\Eddy\AppData\Local\Programs\Python\Python311\Lib\logging\__init__.py", line 1113, in emit
    stream.write(msg + self.terminator)
  File "C:\Users\Eddy\AppData\Local\Programs\Python\Python311\Lib\encodings\cp1252.py", line 19, in encode
    return codecs.charmap_encode(input,self.errors,encoding_table)[0]
           ^^^^^^^^^^^^^^^^^^^^^^^^^^^^^^^^^^^^^^^^^^^^^^^^^^^^^^^
UnicodeEncodeError: 'charmap' codec can't encode character '\u2705' in position 32: character maps to <undefined>
Call stack:
  File "C:\Users\Eddy\YTM Capital Dropbox\Eddy Winiarz\Trading\COF\Models\Unfinished Models\Eddy\Python Projects\work_supa\historical g spread\g_sprd_historical_parquet.py", line 167, in <module>
    final_df = process_g_spread_files(logger)
  File "C:\Users\Eddy\YTM Capital Dropbox\Eddy Winiarz\Trading\COF\Models\Unfinished Models\Eddy\Python Projects\work_supa\src\pipeline\g_spread_processor.py", line 917, in process_g_spread_files
    result_df = processor.process_g_spread_files()
  File "C:\Users\Eddy\YTM Capital Dropbox\Eddy Winiarz\Trading\COF\Models\Unfinished Models\Eddy\Python Projects\work_supa\src\pipeline\g_spread_processor.py", line 52, in process_g_spread_files
    universe_df = self._load_universe_reference()
  File "C:\Users\Eddy\YTM Capital Dropbox\Eddy Winiarz\Trading\COF\Models\Unfinished Models\Eddy\Python Projects\work_supa\src\pipeline\g_spread_processor.py", line 221, in _load_universe_reference
    self.logger.info(f"\u2705 Universe data successfully filtered to most recent date with {len(universe_df)} unique securities")
  File "C:\Users\Eddy\YTM Capital Dropbox\Eddy Winiarz\Trading\COF\Models\Unfinished Models\Eddy\Python Projects\work_supa\src\utils\logging.py", line 44, in info
    self.logger.info(msg)
Message: '\u2705 Universe data successfully filtered to most recent date with 2212 unique securities'
Arguments: ()
--- Logging error ---
Traceback (most recent call last):
  File "C:\Users\Eddy\AppData\Local\Programs\Python\Python311\Lib\logging\__init__.py", line 1113, in emit
    stream.write(msg + self.terminator)
  File "C:\Users\Eddy\AppData\Local\Programs\Python\Python311\Lib\encodings\cp1252.py", line 19, in encode
    return codecs.charmap_encode(input,self.errors,encoding_table)[0]
           ^^^^^^^^^^^^^^^^^^^^^^^^^^^^^^^^^^^^^^^^^^^^^^^^^^^^^^^
UnicodeEncodeError: 'charmap' codec can't encode character '\u215d' in position 48: character maps to <undefined>
Call stack:
  File "C:\Users\Eddy\YTM Capital Dropbox\Eddy Winiarz\Trading\COF\Models\Unfinished Models\Eddy\Python Projects\work_supa\historical g spread\g_sprd_historical_parquet.py", line 167, in <module>
    final_df = process_g_spread_files(logger)
  File "C:\Users\Eddy\YTM Capital Dropbox\Eddy Winiarz\Trading\COF\Models\Unfinished Models\Eddy\Python Projects\work_supa\src\pipeline\g_spread_processor.py", line 917, in process_g_spread_files
    result_df = processor.process_g_spread_files()
  File "C:\Users\Eddy\YTM Capital Dropbox\Eddy Winiarz\Trading\COF\Models\Unfinished Models\Eddy\Python Projects\work_supa\src\pipeline\g_spread_processor.py", line 57, in process_g_spread_files
    df_mapped = self._perform_fuzzy_mapping(df, universe_df)
  File "C:\Users\Eddy\YTM Capital Dropbox\Eddy Winiarz\Trading\COF\Models\Unfinished Models\Eddy\Python Projects\work_supa\src\pipeline\g_spread_processor.py", line 311, in _perform_fuzzy_mapping
    self.logger.info(msg)
  File "C:\Users\Eddy\YTM Capital Dropbox\Eddy Winiarz\Trading\COF\Models\Unfinished Models\Eddy\Python Projects\work_supa\src\utils\logging.py", line 44, in info
    self.logger.info(msg)
Message: 'MAPPED: ACACN 4 \u215d 08/15/29 -> ACACN 4 5/8 08/15/29 (Similarity: 89.5%)'
Arguments: ()
Traceback (most recent call last):
  File "C:\Users\Eddy\YTM Capital Dropbox\Eddy Winiarz\Trading\COF\Models\Unfinished Models\Eddy\Python Projects\work_supa\src\pipeline\g_spread_processor.py", line 57, in process_g_spread_files
    df_mapped = self._perform_fuzzy_mapping(df, universe_df)
                ^^^^^^^^^^^^^^^^^^^^^^^^^^^^^^^^^^^^^^^^^^^^
  File "C:\Users\Eddy\YTM Capital Dropbox\Eddy Winiarz\Trading\COF\Models\Unfinished Models\Eddy\Python Projects\work_supa\src\pipeline\g_spread_processor.py", line 313, in _perform_fuzzy_mapping
    print(msg)
  File "C:\Users\Eddy\AppData\Local\Programs\Python\Python311\Lib\encodings\cp1252.py", line 19, in encode
    return codecs.charmap_encode(input,self.errors,encoding_table)[0]
           ^^^^^^^^^^^^^^^^^^^^^^^^^^^^^^^^^^^^^^^^^^^^^^^^^^^^^^^
UnicodeEncodeError: 'charmap' codec can't encode character '\u215d' in position 16: character maps to <undefined>

During handling of the above exception, another exception occurred:

Traceback (most recent call last):
  File "C:\Users\Eddy\YTM Capital Dropbox\Eddy Winiarz\Trading\COF\Models\Unfinished Models\Eddy\Python Projects\work_supa\src\pipeline\g_spread_processor.py", line 917, in process_g_spread_files
    result_df = processor.process_g_spread_files()
                ^^^^^^^^^^^^^^^^^^^^^^^^^^^^^^^^^^
  File "C:\Users\Eddy\YTM Capital Dropbox\Eddy Winiarz\Trading\COF\Models\Unfinished Models\Eddy\Python Projects\work_supa\src\pipeline\g_spread_processor.py", line 88, in process_g_spread_files
    self.logger.error(f"G Spread processing failed: {str(e)}", exc_info=True)
TypeError: LogManager.error() got an unexpected keyword argument 'exc_info'

During handling of the above exception, another exception occurred:

Traceback (most recent call last):
  File "C:\Users\Eddy\YTM Capital Dropbox\Eddy Winiarz\Trading\COF\Models\Unfinished Models\Eddy\Python Projects\work_supa\historical g spread\g_sprd_historical_parquet.py", line 167, in <module>
    final_df = process_g_spread_files(logger)
               ^^^^^^^^^^^^^^^^^^^^^^^^^^^^^^
  File "C:\Users\Eddy\YTM Capital Dropbox\Eddy Winiarz\Trading\COF\Models\Unfinished Models\Eddy\Python Projects\work_supa\src\pipeline\g_spread_processor.py", line 924, in process_g_spread_files
    logger.error(f"G spread processing failed: {str(e)}", exc_info=True)
TypeError: LogManager.error() got an unexpected keyword argument 'exc_info'

During handling of the above exception, another exception occurred:

Traceback (most recent call last):
  File "C:\Users\Eddy\YTM Capital Dropbox\Eddy Winiarz\Trading\COF\Models\Unfinished Models\Eddy\Python Projects\work_supa\historical g spread\g_sprd_historical_parquet.py", line 205, in <module>
    logger.error("Enhanced G spread processing pipeline failed.", exc_info=True)
TypeError: LogManager.error() got an unexpected keyword argument 'exc_info'

[2025-07-04 16:17:22,578] INFO: ‚úÖ universe completed in 0:00:04.640975
[2025-07-04 16:17:22,578] INFO:    Records processed: 21,711
[2025-07-04 16:17:22,578] INFO:    Output files: 1
[2025-07-04 16:17:22,578] INFO: üìç Executing step 2/2: ['runs-monitor', 'gspread-analytics']
[2025-07-04 16:17:22,578] INFO: üîÑ Executing runs-monitor...
[2025-07-04 16:17:22,582] INFO: üîÑ Executing gspread-analytics...
[2025-07-04 16:17:24,917] ERROR: ‚ùå runs-monitor failed after 0:00:02.337718
[2025-07-04 16:17:24,917] ERROR:    Error: Traceback (most recent call last):
  File "C:\Users\Eddy\YTM Capital Dropbox\Eddy Winiarz\Trading\COF\Models\Unfinished Models\Eddy\Python Projects\work_supa\runs\run_monitor.py", line 436, in main
    monitor = RunMonitor()
              ^^^^^^^^^^^^
  File "C:\Users\Eddy\YTM Capital Dropbox\Eddy Winiarz\Trading\COF\Models\Unfinished Models\Eddy\Python Projects\work_supa\runs\run_monitor.py", line 45, in __init__
    print("\U0001f3af ADVANCED RUN MONITOR - TRADING ANALYSIS SYSTEM")
  File "C:\Users\Eddy\AppData\Local\Programs\Python\Python311\Lib\encodings\cp1252.py", line 19, in encode
    return codecs.charmap_encode(input,self.errors,encoding_table)[0]
           ^^^^^^^^^^^^^^^^^^^^^^^^^^^^^^^^^^^^^^^^^^^^^^^^^^^^^^^
UnicodeEncodeError: 'charmap' codec can't encode character '\U0001f3af' in position 0: character maps to <undefined>

During handling of the above exception, another exception occurred:

Traceback (most recent call last):
  File "C:\Users\Eddy\YTM Capital Dropbox\Eddy Winiarz\Trading\COF\Models\Unfinished Models\Eddy\Python Projects\work_supa\runs\run_monitor.py", line 457, in <module>
    results = main() 
              ^^^^^^
  File "C:\Users\Eddy\YTM Capital Dropbox\Eddy Winiarz\Trading\COF\Models\Unfinished Models\Eddy\Python Projects\work_supa\runs\run_monitor.py", line 453, in main
    print(f"\u274c FATAL ERROR: {e}")
  File "C:\Users\Eddy\AppData\Local\Programs\Python\Python311\Lib\encodings\cp1252.py", line 19, in encode
    return codecs.charmap_encode(input,self.errors,encoding_table)[0]
           ^^^^^^^^^^^^^^^^^^^^^^^^^^^^^^^^^^^^^^^^^^^^^^^^^^^^^^^
UnicodeEncodeError: 'charmap' codec can't encode character '\u274c' in position 0: character maps to <undefined>

[2025-07-04 16:17:25,667] ERROR: ‚ùå gspread-analytics failed after 0:00:03.081279
[2025-07-04 16:17:25,667] ERROR:    Error: Traceback (most recent call last):
  File "C:\Users\Eddy\YTM Capital Dropbox\Eddy Winiarz\Trading\COF\Models\Unfinished Models\Eddy\Python Projects\work_supa\historical g spread\g_z.py", line 1059, in <module>
    main() 
    ^^^^^^
  File "C:\Users\Eddy\YTM Capital Dropbox\Eddy Winiarz\Trading\COF\Models\Unfinished Models\Eddy\Python Projects\work_supa\historical g spread\g_z.py", line 887, in main
    print("\U0001f680 ULTRA-FAST G-Spread Pairwise Z-Score Analysis with Universe Integration")
  File "C:\Users\Eddy\AppData\Local\Programs\Python\Python311\Lib\encodings\cp1252.py", line 19, in encode
    return codecs.charmap_encode(input,self.errors,encoding_table)[0]
           ^^^^^^^^^^^^^^^^^^^^^^^^^^^^^^^^^^^^^^^^^^^^^^^^^^^^^^^
UnicodeEncodeError: 'charmap' codec can't encode character '\U0001f680' in position 0: character maps to <undefined>

[2025-07-04 16:17:25,667] INFO: üìä PIPELINE EXECUTION REPORT
[2025-07-04 16:17:25,667] INFO: ============================================================
[2025-07-04 16:17:25,668] INFO: Overall Success: ‚ùå
[2025-07-04 16:17:25,668] INFO: Total Duration: 0:00:07.750968
[2025-07-04 16:17:25,668] INFO: Total Records Processed: 43,373
[2025-07-04 16:17:25,668] INFO: Total Output Files: 4
[2025-07-04 16:17:25,668] INFO: 
[2025-07-04 16:17:25,668] INFO: Stage Results:
[2025-07-04 16:17:25,668] INFO: ----------------------------------------
[2025-07-04 16:17:25,668] INFO: ‚úÖ portfolio:
[2025-07-04 16:17:25,668] INFO:    Duration: 0:00:04.161705
[2025-07-04 16:17:25,668] INFO:    Records: 21,662
[2025-07-04 16:17:25,669] INFO:    Files: 1
[2025-07-04 16:17:25,669] INFO: 
[2025-07-04 16:17:25,669] INFO: ‚ùå runs-excel:
[2025-07-04 16:17:25,669] INFO:    Duration: 0:00:03.024701
[2025-07-04 16:17:25,669] INFO:    Records: 0
[2025-07-04 16:17:25,669] INFO:    Files: 1
[2025-07-04 16:17:25,669] INFO: 
[2025-07-04 16:17:25,669] INFO: ‚úÖ universe:
[2025-07-04 16:17:25,669] INFO:    Duration: 0:00:04.640975
[2025-07-04 16:17:25,670] INFO:    Records: 21,711
[2025-07-04 16:17:25,670] INFO:    Files: 1
[2025-07-04 16:17:25,670] INFO: 
[2025-07-04 16:17:25,670] INFO: ‚ùå historical-gspread:
[2025-07-04 16:17:25,670] INFO:    Duration: 0:00:04.260441
[2025-07-04 16:17:25,670] INFO:    Records: 0
[2025-07-04 16:17:25,670] INFO:    Files: 0
[2025-07-04 16:17:25,670] INFO:    Error: --- Logging error ---
Traceback (most recent call last):
  File "C:\Users\Eddy\AppData\Local\Programs\Python\Python311\Lib\logging\__init__.py", line 1113, in emit
    stream.write(msg + self.terminator)
  File "C:\Users\Eddy\AppData\Local\Programs\Python\Python311\Lib\encodings\cp1252.py", line 19, in encode
    return codecs.charmap_encode(input,self.errors,encoding_table)[0]
           ^^^^^^^^^^^^^^^^^^^^^^^^^^^^^^^^^^^^^^^^^^^^^^^^^^^^^^^
UnicodeEncodeError: 'charmap' codec can't encode character '\u2705' in position 32: character maps to <undefined>
Call stack:
  File "C:\Users\Eddy\YTM Capital Dropbox\Eddy Winiarz\Trading\COF\Models\Unfinished Models\Eddy\Python Projects\work_supa\historical g spread\g_sprd_historical_parquet.py", line 167, in <module>
    final_df = process_g_spread_files(logger)
  File "C:\Users\Eddy\YTM Capital Dropbox\Eddy Winiarz\Trading\COF\Models\Unfinished Models\Eddy\Python Projects\work_supa\src\pipeline\g_spread_processor.py", line 917, in process_g_spread_files
    result_df = processor.process_g_spread_files()
  File "C:\Users\Eddy\YTM Capital Dropbox\Eddy Winiarz\Trading\COF\Models\Unfinished Models\Eddy\Python Projects\work_supa\src\pipeline\g_spread_processor.py", line 52, in process_g_spread_files
    universe_df = self._load_universe_reference()
  File "C:\Users\Eddy\YTM Capital Dropbox\Eddy Winiarz\Trading\COF\Models\Unfinished Models\Eddy\Python Projects\work_supa\src\pipeline\g_spread_processor.py", line 221, in _load_universe_reference
    self.logger.info(f"\u2705 Universe data successfully filtered to most recent date with {len(universe_df)} unique securities")
  File "C:\Users\Eddy\YTM Capital Dropbox\Eddy Winiarz\Trading\COF\Models\Unfinished Models\Eddy\Python Projects\work_supa\src\utils\logging.py", line 44, in info
    self.logger.info(msg)
Message: '\u2705 Universe data successfully filtered to most recent date with 2212 unique securities'
Arguments: ()
--- Logging error ---
Traceback (most recent call last):
  File "C:\Users\Eddy\AppData\Local\Programs\Python\Python311\Lib\logging\__init__.py", line 1113, in emit
    stream.write(msg + self.terminator)
  File "C:\Users\Eddy\AppData\Local\Programs\Python\Python311\Lib\encodings\cp1252.py", line 19, in encode
    return codecs.charmap_encode(input,self.errors,encoding_table)[0]
           ^^^^^^^^^^^^^^^^^^^^^^^^^^^^^^^^^^^^^^^^^^^^^^^^^^^^^^^
UnicodeEncodeError: 'charmap' codec can't encode character '\u215d' in position 48: character maps to <undefined>
Call stack:
  File "C:\Users\Eddy\YTM Capital Dropbox\Eddy Winiarz\Trading\COF\Models\Unfinished Models\Eddy\Python Projects\work_supa\historical g spread\g_sprd_historical_parquet.py", line 167, in <module>
    final_df = process_g_spread_files(logger)
  File "C:\Users\Eddy\YTM Capital Dropbox\Eddy Winiarz\Trading\COF\Models\Unfinished Models\Eddy\Python Projects\work_supa\src\pipeline\g_spread_processor.py", line 917, in process_g_spread_files
    result_df = processor.process_g_spread_files()
  File "C:\Users\Eddy\YTM Capital Dropbox\Eddy Winiarz\Trading\COF\Models\Unfinished Models\Eddy\Python Projects\work_supa\src\pipeline\g_spread_processor.py", line 57, in process_g_spread_files
    df_mapped = self._perform_fuzzy_mapping(df, universe_df)
  File "C:\Users\Eddy\YTM Capital Dropbox\Eddy Winiarz\Trading\COF\Models\Unfinished Models\Eddy\Python Projects\work_supa\src\pipeline\g_spread_processor.py", line 311, in _perform_fuzzy_mapping
    self.logger.info(msg)
  File "C:\Users\Eddy\YTM Capital Dropbox\Eddy Winiarz\Trading\COF\Models\Unfinished Models\Eddy\Python Projects\work_supa\src\utils\logging.py", line 44, in info
    self.logger.info(msg)
Message: 'MAPPED: ACACN 4 \u215d 08/15/29 -> ACACN 4 5/8 08/15/29 (Similarity: 89.5%)'
Arguments: ()
Traceback (most recent call last):
  File "C:\Users\Eddy\YTM Capital Dropbox\Eddy Winiarz\Trading\COF\Models\Unfinished Models\Eddy\Python Projects\work_supa\src\pipeline\g_spread_processor.py", line 57, in process_g_spread_files
    df_mapped = self._perform_fuzzy_mapping(df, universe_df)
                ^^^^^^^^^^^^^^^^^^^^^^^^^^^^^^^^^^^^^^^^^^^^
  File "C:\Users\Eddy\YTM Capital Dropbox\Eddy Winiarz\Trading\COF\Models\Unfinished Models\Eddy\Python Projects\work_supa\src\pipeline\g_spread_processor.py", line 313, in _perform_fuzzy_mapping
    print(msg)
  File "C:\Users\Eddy\AppData\Local\Programs\Python\Python311\Lib\encodings\cp1252.py", line 19, in encode
    return codecs.charmap_encode(input,self.errors,encoding_table)[0]
           ^^^^^^^^^^^^^^^^^^^^^^^^^^^^^^^^^^^^^^^^^^^^^^^^^^^^^^^
UnicodeEncodeError: 'charmap' codec can't encode character '\u215d' in position 16: character maps to <undefined>

During handling of the above exception, another exception occurred:

Traceback (most recent call last):
  File "C:\Users\Eddy\YTM Capital Dropbox\Eddy Winiarz\Trading\COF\Models\Unfinished Models\Eddy\Python Projects\work_supa\src\pipeline\g_spread_processor.py", line 917, in process_g_spread_files
    result_df = processor.process_g_spread_files()
                ^^^^^^^^^^^^^^^^^^^^^^^^^^^^^^^^^^
  File "C:\Users\Eddy\YTM Capital Dropbox\Eddy Winiarz\Trading\COF\Models\Unfinished Models\Eddy\Python Projects\work_supa\src\pipeline\g_spread_processor.py", line 88, in process_g_spread_files
    self.logger.error(f"G Spread processing failed: {str(e)}", exc_info=True)
TypeError: LogManager.error() got an unexpected keyword argument 'exc_info'

During handling of the above exception, another exception occurred:

Traceback (most recent call last):
  File "C:\Users\Eddy\YTM Capital Dropbox\Eddy Winiarz\Trading\COF\Models\Unfinished Models\Eddy\Python Projects\work_supa\historical g spread\g_sprd_historical_parquet.py", line 167, in <module>
    final_df = process_g_spread_files(logger)
               ^^^^^^^^^^^^^^^^^^^^^^^^^^^^^^
  File "C:\Users\Eddy\YTM Capital Dropbox\Eddy Winiarz\Trading\COF\Models\Unfinished Models\Eddy\Python Projects\work_supa\src\pipeline\g_spread_processor.py", line 924, in process_g_spread_files
    logger.error(f"G spread processing failed: {str(e)}", exc_info=True)
TypeError: LogManager.error() got an unexpected keyword argument 'exc_info'

During handling of the above exception, another exception occurred:

Traceback (most recent call last):
  File "C:\Users\Eddy\YTM Capital Dropbox\Eddy Winiarz\Trading\COF\Models\Unfinished Models\Eddy\Python Projects\work_supa\historical g spread\g_sprd_historical_parquet.py", line 205, in <module>
    logger.error("Enhanced G spread processing pipeline failed.", exc_info=True)
TypeError: LogManager.error() got an unexpected keyword argument 'exc_info'

[2025-07-04 16:17:25,673] INFO: 
[2025-07-04 16:17:25,673] INFO: ‚ùå runs-monitor:
[2025-07-04 16:17:25,673] INFO:    Duration: 0:00:02.337718
[2025-07-04 16:17:25,673] INFO:    Records: 0
[2025-07-04 16:17:25,673] INFO:    Files: 1
[2025-07-04 16:17:25,673] INFO:    Error: Traceback (most recent call last):
  File "C:\Users\Eddy\YTM Capital Dropbox\Eddy Winiarz\Trading\COF\Models\Unfinished Models\Eddy\Python Projects\work_supa\runs\run_monitor.py", line 436, in main
    monitor = RunMonitor()
              ^^^^^^^^^^^^
  File "C:\Users\Eddy\YTM Capital Dropbox\Eddy Winiarz\Trading\COF\Models\Unfinished Models\Eddy\Python Projects\work_supa\runs\run_monitor.py", line 45, in __init__
    print("\U0001f3af ADVANCED RUN MONITOR - TRADING ANALYSIS SYSTEM")
  File "C:\Users\Eddy\AppData\Local\Programs\Python\Python311\Lib\encodings\cp1252.py", line 19, in encode
    return codecs.charmap_encode(input,self.errors,encoding_table)[0]
           ^^^^^^^^^^^^^^^^^^^^^^^^^^^^^^^^^^^^^^^^^^^^^^^^^^^^^^^
UnicodeEncodeError: 'charmap' codec can't encode character '\U0001f3af' in position 0: character maps to <undefined>

During handling of the above exception, another exception occurred:

Traceback (most recent call last):
  File "C:\Users\Eddy\YTM Capital Dropbox\Eddy Winiarz\Trading\COF\Models\Unfinished Models\Eddy\Python Projects\work_supa\runs\run_monitor.py", line 457, in <module>
    results = main() 
              ^^^^^^
  File "C:\Users\Eddy\YTM Capital Dropbox\Eddy Winiarz\Trading\COF\Models\Unfinished Models\Eddy\Python Projects\work_supa\runs\run_monitor.py", line 453, in main
    print(f"\u274c FATAL ERROR: {e}")
  File "C:\Users\Eddy\AppData\Local\Programs\Python\Python311\Lib\encodings\cp1252.py", line 19, in encode
    return codecs.charmap_encode(input,self.errors,encoding_table)[0]
           ^^^^^^^^^^^^^^^^^^^^^^^^^^^^^^^^^^^^^^^^^^^^^^^^^^^^^^^
UnicodeEncodeError: 'charmap' codec can't encode character '\u274c' in position 0: character maps to <undefined>

[2025-07-04 16:17:25,674] INFO: 
[2025-07-04 16:17:25,674] INFO: ‚ùå gspread-analytics:
[2025-07-04 16:17:25,674] INFO:    Duration: 0:00:03.081279
[2025-07-04 16:17:25,674] INFO:    Records: 0
[2025-07-04 16:17:25,675] INFO:    Files: 0
[2025-07-04 16:17:25,675] INFO:    Error: Traceback (most recent call last):
  File "C:\Users\Eddy\YTM Capital Dropbox\Eddy Winiarz\Trading\COF\Models\Unfinished Models\Eddy\Python Projects\work_supa\historical g spread\g_z.py", line 1059, in <module>
    main() 
    ^^^^^^
  File "C:\Users\Eddy\YTM Capital Dropbox\Eddy Winiarz\Trading\COF\Models\Unfinished Models\Eddy\Python Projects\work_supa\historical g spread\g_z.py", line 887, in main
    print("\U0001f680 ULTRA-FAST G-Spread Pairwise Z-Score Analysis with Universe Integration")
  File "C:\Users\Eddy\AppData\Local\Programs\Python\Python311\Lib\encodings\cp1252.py", line 19, in encode
    return codecs.charmap_encode(input,self.errors,encoding_table)[0]
           ^^^^^^^^^^^^^^^^^^^^^^^^^^^^^^^^^^^^^^^^^^^^^^^^^^^^^^^
UnicodeEncodeError: 'charmap' codec can't encode character '\U0001f680' in position 0: character maps to <undefined>

[2025-07-04 16:17:25,675] INFO: 
[2025-07-04 16:17:25,675] INFO: ============================================================
[2025-07-04 16:17:25,675] INFO: üéâ PIPELINE ORCHESTRATION COMPLETE
[2025-07-04 16:17:25,675] INFO: üèÅ Pipeline orchestrator shutdown complete
